<?xml version='1.0'?>

<robot name="rosbot"
  xmlns:xacro="http://www.ros.org/wiki/xacro">

  <xacro:arg name="robot_namespace" default="rosbot"/>

  <xacro:property name="scale_bot" value="1.0"/>

  <xacro:include filename="$(find EXPROBLAB_Assignment2)/urdf/materials.xacro" />
  <xacro:include filename="$(find EXPROBLAB_Assignment2)/urdf/rosbot.gazebo" />
  <xacro:include filename="$(find EXPROBLAB_Assignment2)/urdf/youbot_arm/arm.urdf.xacro" />

  <link name='base_link'>
    <pose>0 0 0.1 0 0 0</pose>

    <inertial>
      <mass value="5"/>
      <origin xyz="0 0 ${scale_bot*0.04}" rpy=" 0 0 0"/>
      <inertia 
      ixx="0.01" ixy="0.01" ixz="0" 
      iyy="0.01" iyz="0.01" 
      izz="0.01" 
      />
    </inertial>

    <collision name='collision'>
      <origin xyz="0 0 ${scale_bot*0.02}" rpy="0 0 0"/>
      <geometry>
        <box size="${scale_bot*0.20} ${scale_bot*0.15} ${scale_bot*0.04}"/>
      </geometry>
    </collision>

    <visual name='base_link_visual'>
      <origin xyz="0 0 ${scale_bot*-0.02}" rpy=" 1.5707 0 1.5707"/>
      <geometry>
        <mesh filename="package://EXPROBLAB_Assignment2/meshes/box.stl" scale="${scale_bot*0.001} ${scale_bot*0.001} ${scale_bot*0.001}" />
      </geometry>
      <material name="White"/>
    </visual>

  </link>

  <joint name="top_joint" type="fixed">
    <axis xyz="0 1 0" />
    <origin xyz="0 0 0" rpy="0 0 0"/>
    <parent link="base_link"/>
    <child link="top"/>
  </joint>

  <link name='top'>
    <pose>0 0 0 0 0 0</pose>

    <inertial>
      <mass value="0.01"/>
      <origin xyz="0 0 ${scale_bot*0.055}" rpy=" 0 0 0"/>
      <inertia 
      ixx="0.0" ixy="0" ixz="0" 
      iyy="0.0" iyz="0" 
      izz="0.0" 
      />
    </inertial>
    <visual>
      <origin xyz="0 0 ${scale_bot*0.055}" rpy=" 1.5707 0 1.5707"/>
      <geometry>
        <mesh filename="package://EXPROBLAB_Assignment2/meshes/upper.stl" scale="${scale_bot*0.001} ${scale_bot*0.001} ${scale_bot*0.001}" />
      </geometry>
      <material name="Red"/>
    </visual>
  </link>

  <!-- arm link and joint -->
  <xacro:youbot_arm parent="top" name="yb_arm"/>

  <link name="front_left_wheel">
    <collision>
      <origin xyz="0 0 0" rpy="0 0 1.5707"/>
      <geometry>
        <mesh filename="package://EXPROBLAB_Assignment2/meshes/wheel.stl" scale="${scale_bot*0.001} ${scale_bot*0.001} ${scale_bot*0.001}" />
      </geometry>
      <surface>
        <friction>
          <ode>
            <mu>10</mu>
            <mu2>10</mu2>
            <kp value="10000000.0" />
            <kd value="0.0" />
          </ode>
        </friction>
      </surface>
    </collision>
    <visual>
      <origin xyz="0 0 0" rpy="0 0 1.5707"/>
      <geometry>
        <mesh filename="package://EXPROBLAB_Assignment2/meshes/wheel.stl" scale="${scale_bot*0.001} ${scale_bot*0.001} ${scale_bot*0.001}" />
      </geometry>
      <material name="Black"/>
    </visual>
    <inertial>
      <origin xyz="0 0 0" rpy="0 1.5707 1.5707"/>
      <mass value="0.5"/>
      <inertia 
      ixx="0.001" ixy="0.0" ixz="0" 
      iyy="0.001" iyz="0.0" 
      izz="0.001" 
      />
    </inertial>
  </link>

  <link name="front_right_wheel">
    <collision>
      <origin xyz="0 0 0" rpy="0 0 -1.5707"/>
      <geometry>
        <mesh filename="package://EXPROBLAB_Assignment2/meshes/wheel.stl" scale="${scale_bot*0.001} ${scale_bot*0.001} ${scale_bot*0.001}" />
      </geometry>
      <surface>
        <friction>
          <ode>
            <mu>10</mu>
            <mu2>10</mu2>
            <kp value="10000000.0" />
            <kd value="0.0" />
          </ode>
        </friction>
      </surface>
    </collision>
    <visual>
      <origin xyz="0 0 0" rpy="0 0 -1.5707"/>
      <geometry>
        <mesh filename="package://EXPROBLAB_Assignment2/meshes/wheel.stl" scale="${scale_bot*0.001} ${scale_bot*0.001} ${scale_bot*0.001}" />
      </geometry>
      <material name="Black"/>
    </visual>
    <inertial>
      <origin xyz="0 0 0" rpy="0 1.5707 1.5707"/>
      <mass value="0.5"/>
      <inertia 
      ixx="0.001" ixy="0.0" ixz="0" 
      iyy="0.001" iyz="0.0" 
      izz="0.001" 
      />
    </inertial>
  </link>

  <link name="rear_left_wheel">
    <collision>
      <origin xyz="0 0 0" rpy="0 0 1.5707"/>
      <geometry>
        <mesh filename="package://EXPROBLAB_Assignment2/meshes/wheel.stl" scale="${scale_bot*0.001} ${scale_bot*0.001} ${scale_bot*0.001}" />
      </geometry>
      <surface>
        <friction>
          <ode>
            <mu>10</mu>
            <mu2>10</mu2>
            <kp value="10000000.0" />
            <kd value="0.0" />
          </ode>
        </friction>
      </surface>
    </collision>
    <visual>
      <origin xyz="0 0 0" rpy="0 0 1.5707"/>
      <geometry>
        <mesh filename="package://EXPROBLAB_Assignment2/meshes/wheel.stl" scale="${scale_bot*0.001} ${scale_bot*0.001} ${scale_bot*0.001}" />
      </geometry>
      <material name="Black"/>
    </visual>
    <inertial>
      <origin xyz="0 0 0" rpy="0 1.5707 1.5707"/>
      <mass value="0.5"/>
      <inertia 
      ixx="0.001" ixy="0.0" ixz="0" 
      iyy="0.001" iyz="0.0" 
      izz="0.001" 
      />
    </inertial>
  </link>

  <link name="rear_right_wheel">
    <collision>
      <origin xyz="0 0 0" rpy="0 0 -1.5707"/>
      <geometry>
        <mesh filename="package://EXPROBLAB_Assignment2/meshes/wheel.stl" scale="${scale_bot*0.001} ${scale_bot*0.001} ${scale_bot*0.001}" />
      </geometry>
      <surface>
        <friction>
          <ode>
            <mu>10</mu>
            <mu2>10</mu2>
            <kp value="10000000.0" />
            <kd value="0.0" />
          </ode>
        </friction>
      </surface>
    </collision>
    <visual>
      <origin xyz="0 0 0" rpy="0 0 -1.5707"/>
      <geometry>
        <mesh filename="package://EXPROBLAB_Assignment2/meshes/wheel.stl" scale="${scale_bot*0.001} ${scale_bot*0.001} ${scale_bot*0.001}" />
      </geometry>
      <material name="Black"/>
    </visual>
    <inertial>
      <origin xyz="0 0 0" rpy="0 1.5707 1.5707"/>
      <mass value="0.5"/>
      <inertia 
      ixx="0.001" ixy="0.0" ixz="0" 
      iyy="0.001" iyz="0.0" 
      izz="0.001" 
      />
    </inertial>
  </link>


  <joint type="continuous" name="front_left_wheel_hinge">
    <origin xyz="${scale_bot*0.05} ${scale_bot*0.11} 0" rpy="0 0 0"/>
    <child link="front_left_wheel"/>
    <parent link="base_link"/>
    <axis xyz="0 1 0" rpy="0 0 0"/>
    <limit effort="1" velocity="10"/>
    <joint_properties damping="5.0" friction="1.0"/>
  </joint>

  <transmission name="front_left_wheel_trans" type="SimpleTransmission">
    <type>transmission_interface/SimpleTransmission</type>
    <actuator name="front_left_wheel_motor">
      <mechanicalReduction>1</mechanicalReduction>
    </actuator>
    <joint name="front_left_wheel_hinge">
      <hardwareInterface>hardware_interface/EffortJointInterface</hardwareInterface>
    </joint>
  </transmission>

  <joint type="continuous" name="front_right_wheel_hinge">
    <origin xyz="${scale_bot*0.05} ${scale_bot*-0.11} 0" rpy="0 0 0"/>
    <child link="front_right_wheel"/>
    <parent link="base_link"/>
    <axis xyz="0 1 0" rpy="0 0 0"/>
    <limit effort="1" velocity="10"/>
    <joint_properties damping="5.0" friction="1.0"/>
  </joint>

  <transmission name="front_right_wheel_trans" type="SimpleTransmission">
    <type>transmission_interface/SimpleTransmission</type>
    <actuator name="front_right_wheel_motor">
      <mechanicalReduction>1</mechanicalReduction>
    </actuator>
    <joint name="front_right_wheel_hinge">
      <hardwareInterface>hardware_interface/EffortJointInterface</hardwareInterface>
    </joint>
  </transmission>

  <joint type="continuous" name="rear_left_wheel_hinge">
    <origin xyz="${scale_bot*-0.055} ${scale_bot*0.11} 0" rpy="0 0 0"/>
    <child link="rear_left_wheel"/>
    <parent link="base_link"/>
    <axis xyz="0 1 0" rpy="0 0 0"/>
    <limit effort="1" velocity="10"/>
    <joint_properties damping="5.0" friction="1.0"/>
  </joint>

  <transmission name="rear_left_wheel_trans" type="SimpleTransmission">
    <type>transmission_interface/SimpleTransmission</type>
    <actuator name="rear_left_wheel_motor">
      <mechanicalReduction>1</mechanicalReduction>
    </actuator>
    <joint name="rear_left_wheel_hinge">
      <hardwareInterface>hardware_interface/EffortJointInterface</hardwareInterface>
    </joint>
  </transmission>

  <joint type="continuous" name="rear_right_wheel_hinge">
    <origin xyz="${scale_bot*-0.055} ${scale_bot*-0.11} 0" rpy="0 0 0"/>
    <child link="rear_right_wheel"/>
    <parent link="base_link"/>
    <axis xyz="0 1 0" rpy="0 0 0"/>
    <limit effort="1" velocity="10"/>
    <joint_properties damping="5.0" friction="1.0"/>
  </joint>

  <transmission name="rear_right_wheel_trans" type="SimpleTransmission">
    <type>transmission_interface/SimpleTransmission</type>
    <actuator name="rear_right_wheel_motor">
      <mechanicalReduction>1</mechanicalReduction>
    </actuator>
    <joint name="rear_right_wheel_hinge">
      <hardwareInterface>hardware_interface/EffortJointInterface</hardwareInterface>
    </joint>
  </transmission>

  <!-- Orbbec Astra RGBD Camera -->
  <joint name="astra_joint" type="fixed">
    <axis xyz="0 0 0" />
    <origin xyz="0 0 0" rpy="0 0 0"/>
    <parent link="yb_arm_link_5"/>
    <child link="camera_link"/>
  </joint> 

  <link name="camera_link">
    <collision>
      <origin xyz="${scale_bot*0.02} 0 0" rpy="0 0 0"/>
      <geometry>0
        <box size="${scale_bot*0.001} ${scale_bot*0.001} ${scale_bot*0.001}"/>
      </geometry>
    </collision>

    <visual>
      <origin xyz="${scale_bot*0.01} 0 ${scale_bot*0.004}" rpy="1.5707 0 1.5707"/>
      <geometry>
        <mesh filename="package://EXPROBLAB_Assignment2/meshes/astra.stl" scale="${scale_bot*0.001/2} ${scale_bot*0.001/2} ${scale_bot*0.001/2}" />
      </geometry>
      <material name="Black"/>
    </visual>

    <inertial>
      <mass value="1e-5" />
      <origin xyz="0 0 0" rpy="0 0 0"/>
      <inertia ixx="0" ixy="0" ixz="0" iyy="0" iyz="0" izz="0" />
    </inertial>
  </link>


  <joint name="camera_optical_joint" type="fixed">
    <origin xyz="0 0 0" rpy="${-pi/2} 0 ${-pi/2}"/>
    <parent link="camera_link"/>
    <child link="camera_rgb_frame"/>
  </joint>

  <link name="camera_rgb_frame">
  </link>

  <joint name="camera_depth_joint" type="fixed">
    <origin xyz="0 0 0" rpy="${-pi/2} 0 ${-pi/2}"/>
    <parent link="camera_link"/>
    <child link="camera_depth_frame"/>
  </joint>

  <link name="camera_depth_frame">
  </link>

  <joint name="rplidar_joint" type="fixed">
    <axis xyz="0 1 0" />
    <origin xyz="${scale_bot*0.1} 0 ${scale_bot*0.0584}" rpy="0 0 0"/>
    <parent link="base_link"/>
    <child link="laser"/>
  </joint>

  <!-- rplidar Laser -->
  <link name="laser">
    <collision>
      <origin xyz="0 0 0" rpy="1.5707 0 4.71"/>
      <geometry>
        <mesh filename="package://EXPROBLAB_Assignment2/meshes/rplidar.stl" scale="${scale_bot*0.001} ${scale_bot*0.001} ${scale_bot*0.001}" />
      </geometry>
    </collision>

    <visual>
      <origin xyz="0 0 0" rpy="1.5707 0 4.71"/>
      <geometry>
        <mesh filename="package://EXPROBLAB_Assignment2/meshes/rplidar.stl" scale="${scale_bot*0.001} ${scale_bot*0.001} ${scale_bot*0.001}" />
      </geometry>
      <material name="White"/>
    </visual>

    <inertial>
      <mass value="1e-5" />
      <origin xyz="0 0 0" rpy="1.5707 0 4.71"/>
      <inertia ixx="0" ixy="0" ixz="0" iyy="0" iyz="0" izz="0" />
    </inertial>
  </link>

  <joint name="range_fl_joint" type="fixed">
    <axis xyz="0 1 0" />
    <origin xyz="${scale_bot*0.1} ${scale_bot*0.05} ${scale_bot*0.05}" rpy="0 0 0.13 "/>
    <parent link="base_link"/>
    <child link="range_fl"/>
  </joint>
  <link name="range_fl"></link>

  <joint name="range_fr_joint" type="fixed">
    <axis xyz="0 1 0" />
    <origin xyz="${scale_bot*0.1} ${scale_bot*-0.05} ${scale_bot*0.01}" rpy="0 0 -0.13 "/>
    <parent link="base_link"/>
    <child link="range_fr"/>
  </joint>
  <link name="range_fr"></link>

  <joint name="range_rl_joint" type="fixed">
    <axis xyz="0 1 0" />
    <origin xyz="${scale_bot*-0.1} ${scale_bot*0.05} ${scale_bot*0.01}" rpy="0 0 3.01 "/>
    <parent link="base_link"/>
    <child link="range_rl"/>
  </joint>
  <link name="range_rl"></link>

  <joint name="range_rr_joint" type="fixed">
    <axis xyz="0 1 0" />
    <origin xyz="${scale_bot*-0.1} ${scale_bot*-0.05} ${scale_bot*0.01}" rpy="0 0 3.27 "/>
    <parent link="base_link"/>
    <child link="range_rr"/>
  </joint>
  <link name="range_rr"></link>

</robot>